from fastapi import HTTPException
from sqlalchemy.exc import SQLAlchemyError
from sqlalchemy.future import select
from sqlalchemy.orm import Session
from app.api.models import Problem, Subcategory
from app.api.schemas import ProblemCreate, ProblemResponse

async def post_problem(db: Session, problem: ProblemCreate) -> ProblemResponse:
    result = await db.execute(select(Subcategory).filter(Subcategory.id == problem.subcategory_id))
    subcategory = result.scalar_one_or_none()
    if not subcategory: 
        raise HTTPException(status_code=400, detail=f'‚ùå CRUD subcategory id {problem.subcategory_id} not found.')
    
    result = await db.execute(select(Problem).filter(Problem.title == problem.title))
    existing_problem = result.scalar_one_or_none()
    if existing_problem:
        raise HTTPException(status_code=409, detail=f'‚è≠Ô∏è CRUD problem "{problem.title}" already exists.')

    try:
        new_problem = Problem(
            title=problem.title,
            difficulty=problem.difficulty,
            image_urls=problem.image_urls,
            description=problem.description,
            examples=problem.examples,
            constraints=problem.constraints,
            subcategory_id=problem.subcategory_id
        )

        db.add(new_problem)
        await db.commit()
        await db.refresh(new_problem)

        print(f'‚úÖ CRUD successfully created a new problem: {new_problem.title}')
        return ProblemResponse.model_validate(new_problem)

    except SQLAlchemyError as e:
        await db.rollback()
        print(f'üö® CRUD database error: {str(e)}')
        raise HTTPException(status_code=500, detail='Database error occurred from CRUD.')

    except Exception as e:
        print(f'üö® CRUD unexpected error: {str(e)}')
        raise HTTPException(status_code=500, detail='Internal Server Error from CRUD.')
    